[DR] Mid-training crash recovery
[DR] Start training session
Traceback (most recent call last):
  File "/Users/saish/Downloads/clyrai_aegis/.venv/lib/python3.13/site-packages/httpx/_transports/default.py", line 101, in map_httpcore_exceptions
    yield
  File "/Users/saish/Downloads/clyrai_aegis/.venv/lib/python3.13/site-packages/httpx/_transports/default.py", line 250, in handle_request
    resp = self._pool.handle_request(req)
  File "/Users/saish/Downloads/clyrai_aegis/.venv/lib/python3.13/site-packages/httpcore/_sync/connection_pool.py", line 256, in handle_request
    raise exc from None
  File "/Users/saish/Downloads/clyrai_aegis/.venv/lib/python3.13/site-packages/httpcore/_sync/connection_pool.py", line 236, in handle_request
    response = connection.handle_request(
        pool_request.request
    )
  File "/Users/saish/Downloads/clyrai_aegis/.venv/lib/python3.13/site-packages/httpcore/_sync/connection.py", line 101, in handle_request
    raise exc
  File "/Users/saish/Downloads/clyrai_aegis/.venv/lib/python3.13/site-packages/httpcore/_sync/connection.py", line 78, in handle_request
    stream = self._connect(request)
  File "/Users/saish/Downloads/clyrai_aegis/.venv/lib/python3.13/site-packages/httpcore/_sync/connection.py", line 124, in _connect
    stream = self._network_backend.connect_tcp(**kwargs)
  File "/Users/saish/Downloads/clyrai_aegis/.venv/lib/python3.13/site-packages/httpcore/_backends/sync.py", line 207, in connect_tcp
    with map_exceptions(exc_map):
         ~~~~~~~~~~~~~~^^^^^^^^^
  File "/opt/homebrew/Cellar/python@3.13/3.13.3/Frameworks/Python.framework/Versions/3.13/lib/python3.13/contextlib.py", line 162, in __exit__
    self.gen.throw(value)
    ~~~~~~~~~~~~~~^^^^^^^
  File "/Users/saish/Downloads/clyrai_aegis/.venv/lib/python3.13/site-packages/httpcore/_exceptions.py", line 14, in map_exceptions
    raise to_exc(exc) from exc
httpcore.ConnectError: [Errno 61] Connection refused

The above exception was the direct cause of the following exception:

Traceback (most recent call last):
  File "<stdin>", line 3, in <module>
  File "/Users/saish/Downloads/clyrai_aegis/.venv/lib/python3.13/site-packages/httpx/_api.py", line 304, in post
    return request(
        "POST",
    ...<13 lines>...
        trust_env=trust_env,
    )
  File "/Users/saish/Downloads/clyrai_aegis/.venv/lib/python3.13/site-packages/httpx/_api.py", line 109, in request
    return client.request(
           ~~~~~~~~~~~~~~^
        method=method,
        ^^^^^^^^^^^^^^
    ...<8 lines>...
        follow_redirects=follow_redirects,
        ^^^^^^^^^^^^^^^^^^^^^^^^^^^^^^^^^^
    )
    ^
  File "/Users/saish/Downloads/clyrai_aegis/.venv/lib/python3.13/site-packages/httpx/_client.py", line 825, in request
    return self.send(request, auth=auth, follow_redirects=follow_redirects)
           ~~~~~~~~~^^^^^^^^^^^^^^^^^^^^^^^^^^^^^^^^^^^^^^^^^^^^^^^^^^^^^^^
  File "/Users/saish/Downloads/clyrai_aegis/.venv/lib/python3.13/site-packages/httpx/_client.py", line 914, in send
    response = self._send_handling_auth(
        request,
    ...<2 lines>...
        history=[],
    )
  File "/Users/saish/Downloads/clyrai_aegis/.venv/lib/python3.13/site-packages/httpx/_client.py", line 942, in _send_handling_auth
    response = self._send_handling_redirects(
        request,
        follow_redirects=follow_redirects,
        history=history,
    )
  File "/Users/saish/Downloads/clyrai_aegis/.venv/lib/python3.13/site-packages/httpx/_client.py", line 979, in _send_handling_redirects
    response = self._send_single_request(request)
  File "/Users/saish/Downloads/clyrai_aegis/.venv/lib/python3.13/site-packages/httpx/_client.py", line 1014, in _send_single_request
    response = transport.handle_request(request)
  File "/Users/saish/Downloads/clyrai_aegis/.venv/lib/python3.13/site-packages/httpx/_transports/default.py", line 249, in handle_request
    with map_httpcore_exceptions():
         ~~~~~~~~~~~~~~~~~~~~~~~^^
  File "/opt/homebrew/Cellar/python@3.13/3.13.3/Frameworks/Python.framework/Versions/3.13/lib/python3.13/contextlib.py", line 162, in __exit__
    self.gen.throw(value)
    ~~~~~~~~~~~~~~^^^^^^^
  File "/Users/saish/Downloads/clyrai_aegis/.venv/lib/python3.13/site-packages/httpx/_transports/default.py", line 118, in map_httpcore_exceptions
    raise mapped_exc(message) from exc
httpx.ConnectError: [Errno 61] Connection refused
